File: dd/res/SIGEPS
step($1) time(ns)($2) stress(MPa): [11]($3) [22]($4) [33]($5) [12]($6) [13]($7) [23]($8) total strain: [11]($9) [22]($10) [33]($11) [12]($12) [13]($13) [23]($14) plastic strain:  [11]($15) [22]($16) [33]($17) [12]($18) [13]($19) [23]($20)
1 1e-05 0 0 0 0 0 0 0 0 0 0 0 0 0 0 0 0 0 0
2 2e-05 0 0 0 0 0 0 0 0 0 0 0 0 0 0 0 0 0 0
3 3e-05 0 0 0 0 0 0 0 0 0 0 0 0 0 0 0 0 0 0
4 4e-05 0 0 0 0 0 0 0 0 0 0 0 0 0 0 0 0 0 0
5 5e-05 0 0 0 0 0 0 0 0 0 0 0 0 0 0 0 0 0 0
6 6e-05 0 0 0 0 0 0 0 0 0 0 0 0 0 0 0 0 0 0
7 7e-05 0 0 0 0 0 0 0 0 0 0 0 0 0 0 0 0 0 0
8 8e-05 0 0 0 0 0 0 0 0 0 0 0 0 0 0 0 0 0 0
9 9e-05 0 0 0 0 0 0 0 0 0 0 0 0 0 0 0 0 0 0
10 0.0001 0 0 0 0 0 0 0 0 0 0 0 0 0 0 0 0 0 0
11 0.00011 0 0 0 0 0 0 0 0 0 0 0 0 0 0 0 0 0 0
12 0.00012 0 0 0 0 0 0 0 0 0 0 0 0 0 0 0 0 0 0
13 0.00013 0 0 0 0 0 0 0 0 0 0 0 0 0 0 0 0 0 0
14 0.00014 0 0 0 0 0 0 0 0 0 0 0 0 0 0 0 0 0 0
15 0.00015 0 0 0 0 0 0 0 0 0 0 0 0 0 0 0 0 0 0
16 0.00016 0 0 0 0 0 0 0 0 0 0 0 0 0 0 0 0 0 0
17 0.00017 0 0 0 0 0 0 0 0 0 0 0 0 0 0 0 0 0 0
18 0.00018 0 0 0 0 0 0 0 0 0 0 0 0 0 0 0 0 0 0
19 0.00019 0 0 0 0 0 0 0 0 0 0 0 0 0 0 0 0 0 0
20 0.0002 0 0 0 0 0 0 0 0 0 0 0 0 0 0 0 0 0 0
21 0.00021 0 0 0 0 0 0 0 0 0 0 0 0 0 0 0 0 0 0
22 0.00022 0 0 0 0 0 0 0 0 0 0 0 0 0 0 0 0 0 0
23 0.00023 0 0 0 0 0 0 0 0 0 0 0 0 0 0 0 0 0 0
24 0.00024 0 0 0 0 0 0 0 0 0 0 0 0 0 0 0 0 0 0
25 0.00025 0 0 0 0 0 0 0 0 0 0 0 0 0 0 0 0 0 0
26 0.00026 0 0 0 0 0 0 0 0 0 0 0 0 0 0 0 0 0 0
27 0.00027 0 0 0 0 0 0 0 0 0 0 0 0 0 0 0 0 0 0
28 0.00028 0 0 0 0 0 0 0 0 0 0 0 0 0 0 0 0 0 0
29 0.00029 0 0 0 0 0 0 0 0 0 0 0 0 0 0 0 0 0 0
30 0.0003 0 0 0 0 0 0 0 0 0 0 0 0 0 0 0 0 0 0
31 0.00031 0 0 0 0 0 0 0 0 0 0 0 0 0 0 0 0 0 0
32 0.00032 0 0 0 0 0 0 0 0 0 0 0 0 0 0 0 0 0 0
33 0.00033 0 0 0 0 0 0 0 0 0 0 0 0 0 0 0 0 0 0
34 0.00034 0 0 0 0 0 0 0 0 0 0 0 0 0 0 0 0 0 0
35 0.00035 0 0 0 0 0 0 0 0 0 0 0 0 0 0 0 0 0 0
36 0.00036 0 0 0 0 0 0 0 0 0 0 0 0 0 0 0 0 0 0
37 0.00037 0 0 0 0 0 0 0 0 0 0 0 0 0 0 0 0 0 0
38 0.00038 0 0 0 0 0 0 0 0 0 0 0 0 0 0 0 0 0 0
39 0.00039 0 0 0 0 0 0 0 0 0 0 0 0 0 0 0 0 0 0
40 0.0004 0 0 0 0 0 0 0 0 0 0 0 0 0 0 0 0 0 0
41 0.00041 0 0 0 0 0 0 0 0 0 0 0 0 0 0 0 0 0 0
42 0.00042 0 0 0 0 0 0 0 0 0 0 0 0 0 0 0 0 0 0
43 0.00043 0 0 0 0 0 0 0 0 0 0 0 0 0 0 0 0 0 0
44 0.00044 0 0 0 0 0 0 0 0 0 0 0 0 0 0 0 0 0 0
45 0.00045 0 0 0 0 0 0 0 0 0 0 0 0 0 0 0 0 0 0
46 0.00046 0 0 0 0 0 0 0 0 0 0 0 0 0 0 0 0 0 0
47 0.00047 0 0 0 0 0 0 0 0 0 0 0 0 0 0 0 0 0 0
48 0.00048 0 0 0 0 0 0 0 0 0 0 0 0 0 0 0 0 0 0
49 0.00049 0 0 0 0 0 0 0 0 0 0 0 0 0 0 0 0 0 0
50 0.0005 0 0 0 0 0 0 0 0 0 0 0 0 0 0 0 0 0 0
51 0.00051 0 0 0 0 0 0 0 0 0 0 0 0 0 0 0 0 0 0
52 0.00052 0 0 0 0 0 0 0 0 0 0 0 0 0 0 0 0 0 0
53 0.00053 0 0 0 0 0 0 0 0 0 0 0 0 0 0 0 0 0 0
54 0.00054 0 0 0 0 0 0 0 0 0 0 0 0 0 0 0 0 0 0
55 0.00055 0 0 0 0 0 0 0 0 0 0 0 0 0 0 0 0 0 0
56 0.00056 0 0 0 0 0 0 0 0 0 0 0 0 0 0 0 0 0 0
57 0.00057 0 0 0 0 0 0 0 0 0 0 0 0 0 0 0 0 0 0
58 0.00058 0 0 0 0 0 0 0 0 0 0 0 0 0 0 0 0 0 0
59 0.00059 0 0 0 0 0 0 0 0 0 0 0 0 0 0 0 0 0 0
60 0.0006 0 0 0 0 0 0 0 0 0 0 0 0 0 0 0 0 0 0
61 0.00061 0 0 0 0 0 0 0 0 0 0 0 0 0 0 0 0 0 0
62 0.00062 0 0 0 0 0 0 0 0 0 0 0 0 0 0 0 0 0 0
63 0.00063 0 0 0 0 0 0 0 0 0 0 0 0 0 0 0 0 0 0
64 0.00064 0 0 0 0 0 0 0 0 0 0 0 0 0 0 0 0 0 0
65 0.00065 0 0 0 0 0 0 0 0 0 0 0 0 0 0 0 0 0 0
66 0.00066 0 0 0 0 0 0 0 0 0 0 0 0 0 0 0 0 0 0
67 0.00067 0 0 0 0 0 0 0 0 0 0 0 0 0 0 0 0 0 0
68 0.00068 0 0 0 0 0 0 0 0 0 0 0 0 0 0 0 0 0 0
69 0.00069 0 0 0 0 0 0 0 0 0 0 0 0 0 0 0 0 0 0
70 0.0007 0 0 0 0 0 0 0 0 0 0 0 0 0 0 0 0 0 0
71 0.00071 0 0 0 0 0 0 0 0 0 0 0 0 0 0 0 0 0 0
72 0.00072 0 0 0 0 0 0 0 0 0 0 0 0 0 0 0 0 0 0
73 0.00073 0 0 0 0 0 0 0 0 0 0 0 0 0 0 0 0 0 0
74 0.00074 0 0 0 0 0 0 0 0 0 0 0 0 0 0 0 0 0 0
75 0.00075 0 0 0 0 0 0 0 0 0 0 0 0 0 0 0 0 0 0
76 0.00076 0 0 0 0 0 0 0 0 0 0 0 0 0 0 0 0 0 0
77 0.00077 0 0 0 0 0 0 0 0 0 0 0 0 0 0 0 0 0 0
78 0.00078 0 0 0 0 0 0 0 0 0 0 0 0 0 0 0 0 0 0
79 0.00079 0 0 0 0 0 0 0 0 0 0 0 0 0 0 0 0 0 0
80 0.0008 0 0 0 0 0 0 0 0 0 0 0 0 0 0 0 0 0 0
81 0.00081 0 0 0 0 0 0 0 0 0 0 0 0 0 0 0 0 0 0
82 0.00082 0 0 0 0 0 0 0 0 0 0 0 0 0 0 0 0 0 0
83 0.00083 0 0 0 0 0 0 0 0 0 0 0 0 0 0 0 0 0 0
84 0.00084 0 0 0 0 0 0 0 0 0 0 0 0 0 0 0 0 0 0
85 0.00085 0 0 0 0 0 0 0 0 0 0 0 0 0 0 0 0 0 0
86 0.00086 0 0 0 0 0 0 0 0 0 0 0 0 0 0 0 0 0 0
87 0.00087 0 0 0 0 0 0 0 0 0 0 0 0 0 0 0 0 0 0
88 0.00088 0 0 0 0 0 0 0 0 0 0 0 0 0 0 0 0 0 0
89 0.00089 0 0 0 0 0 0 0 0 0 0 0 0 0 0 0 0 0 0
90 0.0009 0 0 0 0 0 0 0 0 0 0 0 0 0 0 0 0 0 0
91 0.00091 0 0 0 0 0 0 0 0 0 0 0 0 0 0 0 0 0 0
92 0.00092 0 0 0 0 0 0 0 0 0 0 0 0 0 0 0 0 0 0
93 0.00093 0 0 0 0 0 0 0 0 0 0 0 0 0 0 0 0 0 0
94 0.00094 0 0 0 0 0 0 0 0 0 0 0 0 0 0 0 0 0 0
95 0.00095 0 0 0 0 0 0 0 0 0 0 0 0 0 0 0 0 0 0
96 0.00096 0 0 0 0 0 0 0 0 0 0 0 0 0 0 0 0 0 0
97 0.00097 0 0 0 0 0 0 0 0 0 0 0 0 0 0 0 0 0 0
98 0.00098 0 0 0 0 0 0 0 0 0 0 0 0 0 0 0 0 0 0
99 0.00099 0 0 0 0 0 0 0 0 0 0 0 0 0 0 0 0 0 0
100 0.001 0 0 0 0 0 0 0 0 0 0 0 0 0 0 0 0 0 0